Downloading: "https://download.pytorch.org/models/resnet101-5d3b4d8f.pth" to user-directory-path/resnet101-5d3b4d8f.pth
Traceback (most recent call last):
  File "/home/alex039u2/data/anaconda3/lib/python3.7/site-packages/urllib3/connection.py", line 171, in _new_conn
    (self._dns_host, self.port), self.timeout, **extra_kw)
  File "/home/alex039u2/data/anaconda3/lib/python3.7/site-packages/urllib3/util/connection.py", line 79, in create_connection
    raise err
  File "/home/alex039u2/data/anaconda3/lib/python3.7/site-packages/urllib3/util/connection.py", line 69, in create_connection
    sock.connect(sa)
OSError: [Errno 101] Network is unreachable

During handling of the above exception, another exception occurred:

Traceback (most recent call last):
  File "/home/alex039u2/data/anaconda3/lib/python3.7/site-packages/urllib3/connectionpool.py", line 600, in urlopen
    chunked=chunked)
  File "/home/alex039u2/data/anaconda3/lib/python3.7/site-packages/urllib3/connectionpool.py", line 343, in _make_request
    self._validate_conn(conn)
  File "/home/alex039u2/data/anaconda3/lib/python3.7/site-packages/urllib3/connectionpool.py", line 849, in _validate_conn
    conn.connect()
  File "/home/alex039u2/data/anaconda3/lib/python3.7/site-packages/urllib3/connection.py", line 314, in connect
    conn = self._new_conn()
  File "/home/alex039u2/data/anaconda3/lib/python3.7/site-packages/urllib3/connection.py", line 180, in _new_conn
    self, "Failed to establish a new connection: %s" % e)
urllib3.exceptions.NewConnectionError: <urllib3.connection.VerifiedHTTPSConnection object at 0x7f5d69ab7b00>: Failed to establish a new connection: [Errno 101] Network is unreachable

During handling of the above exception, another exception occurred:

Traceback (most recent call last):
  File "/home/alex039u2/data/anaconda3/lib/python3.7/site-packages/requests/adapters.py", line 445, in send
    timeout=timeout
  File "/home/alex039u2/data/anaconda3/lib/python3.7/site-packages/urllib3/connectionpool.py", line 638, in urlopen
    _stacktrace=sys.exc_info()[2])
  File "/home/alex039u2/data/anaconda3/lib/python3.7/site-packages/urllib3/util/retry.py", line 398, in increment
    raise MaxRetryError(_pool, url, error or ResponseError(cause))
urllib3.exceptions.MaxRetryError: HTTPSConnectionPool(host='download.pytorch.org', port=443): Max retries exceeded with url: /models/resnet101-5d3b4d8f.pth (Caused by NewConnectionError('<urllib3.connection.VerifiedHTTPSConnection object at 0x7f5d69ab7b00>: Failed to establish a new connection: [Errno 101] Network is unreachable'))

During handling of the above exception, another exception occurred:

Traceback (most recent call last):
  File "download_model.py", line 8, in <module>
    base_model = getattr(torchvision.models, 'resnet101')(True)  #downloading thee model
  File "/home/alex039u2/data/anaconda3/lib/python3.7/site-packages/torchvision/models/resnet.py", line 200, in resnet101
    model.load_state_dict(model_zoo.load_url(model_urls['resnet101']))
  File "/home/alex039u2/data/anaconda3/lib/python3.7/site-packages/torch/utils/model_zoo.py", line 66, in load_url
    _download_url_to_file(url, cached_file, hash_prefix, progress=progress)
  File "/home/alex039u2/data/anaconda3/lib/python3.7/site-packages/torch/utils/model_zoo.py", line 72, in _download_url_to_file
    u = urlopen(url, stream=True)
  File "/home/alex039u2/data/anaconda3/lib/python3.7/site-packages/requests/api.py", line 72, in get
    return request('get', url, params=params, **kwargs)
  File "/home/alex039u2/data/anaconda3/lib/python3.7/site-packages/requests/api.py", line 58, in request
    return session.request(method=method, url=url, **kwargs)
  File "/home/alex039u2/data/anaconda3/lib/python3.7/site-packages/requests/sessions.py", line 512, in request
    resp = self.send(prep, **send_kwargs)
  File "/home/alex039u2/data/anaconda3/lib/python3.7/site-packages/requests/sessions.py", line 622, in send
    r = adapter.send(request, **kwargs)
  File "/home/alex039u2/data/anaconda3/lib/python3.7/site-packages/requests/adapters.py", line 513, in send
    raise ConnectionError(e, request=request)
requests.exceptions.ConnectionError: HTTPSConnectionPool(host='download.pytorch.org', port=443): Max retries exceeded with url: /models/resnet101-5d3b4d8f.pth (Caused by NewConnectionError('<urllib3.connection.VerifiedHTTPSConnection object at 0x7f5d69ab7b00>: Failed to establish a new connection: [Errno 101] Network is unreachable'))
